<?xml version="1.0" ?>
<!-- =================================================================================== -->
<!-- |    This document was autogenerated by xacro from kipp.urdf.xacro                | -->
<!-- |    EDITING THIS FILE BY HAND IS NOT RECOMMENDED                                 | -->
<!-- =================================================================================== -->
<robot name="kipp">
  <!-- Robot constants-->
  <!-- Robot Base -->
  <link name="base_link">
    <visual>
      <geometry>
        <box size="0.77975 0.5084 0.51"/>
      </geometry>
      <material name="rover_material">
        <color rgba="0.5 0.5 0.5 1.0"/>
      </material>
    </visual>
    <!-- Added Collision -->
    <collision>
      <origin rpy="0 0 0" xyz="0 0 0"/>
      <geometry>
        <box size="0.77975 0.5084 0.51"/>
      </geometry>
    </collision>
    <!-- Added Inertial (PLACEHOLDER VALUES - UPDATE FOR ACCURACY) -->
    <inertial>
      <mass value="20.0"/>
      <!-- Estimated mass in kg -->
      <origin rpy="0 0 0" xyz="0 0 0"/>
      <!-- Assuming geometric center is CoM -->
      <inertia ixx="1.5" ixy="0.0" ixz="0.0" iyy="2.5" iyz="0.0" izz="3.5"/>
      <!-- Placeholder inertia tensor -->
    </inertial>
  </link>
  <!-- Robot Footprint (Virtual Link - No Collision/Inertial) -->
  <link name="base_footprint"/>
  <joint name="base_joint" type="fixed">
    <parent link="base_link"/>
    <child link="base_footprint"/>
    <origin rpy="0 0 0" xyz="0.0 0.0 -0.43679999999999997"/>
  </joint>
  <link name="front_left_steering_link">
    <visual>
      <origin rpy="0 0 0" xyz="0 0 0"/>
      <geometry>
        <box size="0.06155 0.06155 0.23"/>
      </geometry>
      <material name="Gray">
        <color rgba="0.5 0.5 0.5 1.0"/>
      </material>
    </visual>
    <!-- Added Collision -->
    <collision>
      <origin rpy="0 0 0" xyz="0 0 0"/>
      <geometry>
        <box size="0.06155 0.06155 0.23"/>
      </geometry>
    </collision>
    <!-- Added Inertial (PLACEHOLDER VALUES - UPDATE FOR ACCURACY) -->
    <inertial>
      <mass value="0.2"/>
      <!-- Estimated mass in kg -->
      <origin rpy="0 0 0" xyz="0 0 0"/>
      <inertia ixx="0.0001" ixy="0.0" ixz="0.0" iyy="0.0001" iyz="0.0" izz="0.0001"/>
      <!-- Placeholder inertia tensor -->
    </inertial>
  </link>
  <joint name="front_left_steering_joint" type="revolute">
    <parent link="base_link"/>
    <child link="front_left_steering_link"/>
    <axis xyz="0 0 1"/>
    <origin rpy="0 0 0" xyz="0.389875 0.2542 -0.255"/>
    <limit effort="10.0" lower="-1.5707846" upper="1.5707846" velocity="1.0"/>
    <!-- Added effort/velocity limits -->
  </joint>
  <link name="front_right_steering_link">
    <visual>
      <origin rpy="0 0 0" xyz="0 0 0"/>
      <geometry>
        <box size="0.06155 0.06155 0.23"/>
      </geometry>
      <material name="Gray">
        <color rgba="0.5 0.5 0.5 1.0"/>
      </material>
    </visual>
    <!-- Added Collision -->
    <collision>
      <origin rpy="0 0 0" xyz="0 0 0"/>
      <geometry>
        <box size="0.06155 0.06155 0.23"/>
      </geometry>
    </collision>
    <!-- Added Inertial (PLACEHOLDER VALUES - UPDATE FOR ACCURACY) -->
    <inertial>
      <mass value="0.2"/>
      <!-- Estimated mass in kg -->
      <origin rpy="0 0 0" xyz="0 0 0"/>
      <inertia ixx="0.0001" ixy="0.0" ixz="0.0" iyy="0.0001" iyz="0.0" izz="0.0001"/>
      <!-- Placeholder inertia tensor -->
    </inertial>
  </link>
  <joint name="front_right_steering_joint" type="revolute">
    <parent link="base_link"/>
    <child link="front_right_steering_link"/>
    <axis xyz="0 0 1"/>
    <origin rpy="0 0 0" xyz="0.389875 -0.2542 -0.255"/>
    <limit effort="10.0" lower="-1.5707846" upper="1.5707846" velocity="1.0"/>
    <!-- Added effort/velocity limits -->
  </joint>
  <link name="back_left_steering_link">
    <visual>
      <origin rpy="0 0 0" xyz="0 0 0"/>
      <geometry>
        <box size="0.06155 0.06155 0.23"/>
      </geometry>
      <material name="Gray">
        <color rgba="0.5 0.5 0.5 1.0"/>
      </material>
    </visual>
    <!-- Added Collision -->
    <collision>
      <origin rpy="0 0 0" xyz="0 0 0"/>
      <geometry>
        <box size="0.06155 0.06155 0.23"/>
      </geometry>
    </collision>
    <!-- Added Inertial (PLACEHOLDER VALUES - UPDATE FOR ACCURACY) -->
    <inertial>
      <mass value="0.2"/>
      <!-- Estimated mass in kg -->
      <origin rpy="0 0 0" xyz="0 0 0"/>
      <inertia ixx="0.0001" ixy="0.0" ixz="0.0" iyy="0.0001" iyz="0.0" izz="0.0001"/>
      <!-- Placeholder inertia tensor -->
    </inertial>
  </link>
  <joint name="back_left_steering_joint" type="revolute">
    <parent link="base_link"/>
    <child link="back_left_steering_link"/>
    <axis xyz="0 0 1"/>
    <origin rpy="0 0 0" xyz="-0.389875 0.2542 -0.255"/>
    <limit effort="10.0" lower="-1.5707846" upper="1.5707846" velocity="1.0"/>
    <!-- Added effort/velocity limits -->
  </joint>
  <link name="back_right_steering_link">
    <visual>
      <origin rpy="0 0 0" xyz="0 0 0"/>
      <geometry>
        <box size="0.06155 0.06155 0.23"/>
      </geometry>
      <material name="Gray">
        <color rgba="0.5 0.5 0.5 1.0"/>
      </material>
    </visual>
    <!-- Added Collision -->
    <collision>
      <origin rpy="0 0 0" xyz="0 0 0"/>
      <geometry>
        <box size="0.06155 0.06155 0.23"/>
      </geometry>
    </collision>
    <!-- Added Inertial (PLACEHOLDER VALUES - UPDATE FOR ACCURACY) -->
    <inertial>
      <mass value="0.2"/>
      <!-- Estimated mass in kg -->
      <origin rpy="0 0 0" xyz="0 0 0"/>
      <inertia ixx="0.0001" ixy="0.0" ixz="0.0" iyy="0.0001" iyz="0.0" izz="0.0001"/>
      <!-- Placeholder inertia tensor -->
    </inertial>
  </link>
  <joint name="back_right_steering_joint" type="revolute">
    <parent link="base_link"/>
    <child link="back_right_steering_link"/>
    <axis xyz="0 0 1"/>
    <origin rpy="0 0 0" xyz="-0.389875 -0.2542 -0.255"/>
    <limit effort="10.0" lower="-1.5707846" upper="1.5707846" velocity="1.0"/>
    <!-- Added effort/velocity limits -->
  </joint>
  <link name="front_left_wheel_link">
    <visual>
      <origin rpy="1.5707846 0 0" xyz="0 0 0"/>
      <geometry>
        <cylinder length="0.1016" radius="0.0909"/>
      </geometry>
      <material name="black">
        <color rgba="0.0 0.0 0.0 1.0"/>
      </material>
    </visual>
    <!-- Added Collision -->
    <collision>
      <origin rpy="1.5707846 0 0" xyz="0 0 0"/>
      <geometry>
        <cylinder length="0.1016" radius="0.0909"/>
      </geometry>
    </collision>
    <!-- Added Inertial (PLACEHOLDER VALUES - UPDATE FOR ACCURACY) -->
    <inertial>
      <mass value="0.5"/>
      <!-- Estimated wheel mass in kg -->
      <origin rpy="1.5707846 0 0" xyz="0 0 0"/>
      <inertia ixx="0.001" ixy="0.0" ixz="0.0" iyy="0.0005" iyz="0.0" izz="0.0005"/>
      <!-- Placeholder inertia tensor for cylinder on X-axis -->
    </inertial>
  </link>
  <joint name="front_left_wheel_joint" type="continuous">
    <!-- Changed to continuous -->
    <parent link="front_left_steering_link"/>
    <!-- **** CHANGED PARENT TO STEERING LINK **** -->
    <child link="front_left_wheel_link"/>
    <!-- Wheel origin relative to steering link -->
    <origin rpy="0 0 0" xyz="0 0 -0.115"/>
    <axis xyz="0 1 0"/>
    <!-- Axis of rotation for driving -->
    <!-- Add limits if needed for continuous, usually not -->
  </joint>
  <link name="front_right_wheel_link">
    <visual>
      <origin rpy="1.5707846 0 0" xyz="0 0 0"/>
      <geometry>
        <cylinder length="0.1016" radius="0.0909"/>
      </geometry>
      <material name="black">
        <color rgba="0.0 0.0 0.0 1.0"/>
      </material>
    </visual>
    <!-- Added Collision -->
    <collision>
      <origin rpy="1.5707846 0 0" xyz="0 0 0"/>
      <geometry>
        <cylinder length="0.1016" radius="0.0909"/>
      </geometry>
    </collision>
    <!-- Added Inertial (PLACEHOLDER VALUES - UPDATE FOR ACCURACY) -->
    <inertial>
      <mass value="0.5"/>
      <!-- Estimated wheel mass in kg -->
      <origin rpy="1.5707846 0 0" xyz="0 0 0"/>
      <inertia ixx="0.001" ixy="0.0" ixz="0.0" iyy="0.0005" iyz="0.0" izz="0.0005"/>
      <!-- Placeholder inertia tensor for cylinder on X-axis -->
    </inertial>
  </link>
  <joint name="front_right_wheel_joint" type="continuous">
    <!-- Changed to continuous -->
    <parent link="front_right_steering_link"/>
    <!-- **** CHANGED PARENT TO STEERING LINK **** -->
    <child link="front_right_wheel_link"/>
    <!-- Wheel origin relative to steering link -->
    <origin rpy="0 0 0" xyz="0 0 -0.115"/>
    <axis xyz="0 1 0"/>
    <!-- Axis of rotation for driving -->
    <!-- Add limits if needed for continuous, usually not -->
  </joint>
  <link name="back_left_wheel_link">
    <visual>
      <origin rpy="1.5707846 0 0" xyz="0 0 0"/>
      <geometry>
        <cylinder length="0.1016" radius="0.0909"/>
      </geometry>
      <material name="black">
        <color rgba="0.0 0.0 0.0 1.0"/>
      </material>
    </visual>
    <!-- Added Collision -->
    <collision>
      <origin rpy="1.5707846 0 0" xyz="0 0 0"/>
      <geometry>
        <cylinder length="0.1016" radius="0.0909"/>
      </geometry>
    </collision>
    <!-- Added Inertial (PLACEHOLDER VALUES - UPDATE FOR ACCURACY) -->
    <inertial>
      <mass value="0.5"/>
      <!-- Estimated wheel mass in kg -->
      <origin rpy="1.5707846 0 0" xyz="0 0 0"/>
      <inertia ixx="0.001" ixy="0.0" ixz="0.0" iyy="0.0005" iyz="0.0" izz="0.0005"/>
      <!-- Placeholder inertia tensor for cylinder on X-axis -->
    </inertial>
  </link>
  <joint name="back_left_wheel_joint" type="continuous">
    <!-- Changed to continuous -->
    <parent link="back_left_steering_link"/>
    <!-- **** CHANGED PARENT TO STEERING LINK **** -->
    <child link="back_left_wheel_link"/>
    <!-- Wheel origin relative to steering link -->
    <origin rpy="0 0 0" xyz="0 0 -0.115"/>
    <axis xyz="0 1 0"/>
    <!-- Axis of rotation for driving -->
    <!-- Add limits if needed for continuous, usually not -->
  </joint>
  <link name="back_right_wheel_link">
    <visual>
      <origin rpy="1.5707846 0 0" xyz="0 0 0"/>
      <geometry>
        <cylinder length="0.1016" radius="0.0909"/>
      </geometry>
      <material name="black">
        <color rgba="0.0 0.0 0.0 1.0"/>
      </material>
    </visual>
    <!-- Added Collision -->
    <collision>
      <origin rpy="1.5707846 0 0" xyz="0 0 0"/>
      <geometry>
        <cylinder length="0.1016" radius="0.0909"/>
      </geometry>
    </collision>
    <!-- Added Inertial (PLACEHOLDER VALUES - UPDATE FOR ACCURACY) -->
    <inertial>
      <mass value="0.5"/>
      <!-- Estimated wheel mass in kg -->
      <origin rpy="1.5707846 0 0" xyz="0 0 0"/>
      <inertia ixx="0.001" ixy="0.0" ixz="0.0" iyy="0.0005" iyz="0.0" izz="0.0005"/>
      <!-- Placeholder inertia tensor for cylinder on X-axis -->
    </inertial>
  </link>
  <joint name="back_right_wheel_joint" type="continuous">
    <!-- Changed to continuous -->
    <parent link="back_right_steering_link"/>
    <!-- **** CHANGED PARENT TO STEERING LINK **** -->
    <child link="back_right_wheel_link"/>
    <!-- Wheel origin relative to steering link -->
    <origin rpy="0 0 0" xyz="0 0 -0.115"/>
    <axis xyz="0 1 0"/>
    <!-- Axis of rotation for driving -->
    <!-- Add limits if needed for continuous, usually not -->
  </joint>
  <!-- Middle Left Wheel -->
  <link name="middle_left_wheel_link">
    <visual>
      <origin rpy="1.5707846 0 0" xyz="0 0 0"/>
      <geometry>
        <cylinder length="0.1016" radius="0.0909"/>
      </geometry>
      <material name="black"/>
    </visual>
    <!-- Added Collision -->
    <collision>
      <origin rpy="1.5707846 0 0" xyz="0 0 0"/>
      <geometry>
        <cylinder length="0.1016" radius="0.0909"/>
      </geometry>
    </collision>
    <!-- Added Inertial (PLACEHOLDER VALUES - UPDATE FOR ACCURACY) -->
    <inertial>
      <mass value="0.5"/>
      <!-- Estimated wheel mass in kg -->
      <origin rpy="1.5707846 0 0" xyz="0 0 0"/>
      <inertia ixx="0.001" ixy="0.0" ixz="0.0" iyy="0.0005" iyz="0.0" izz="0.0005"/>
      <!-- Placeholder inertia tensor -->
    </inertial>
  </link>
  <joint name="middle_left_wheel_joint" type="continuous">
    <parent link="base_link"/>
    <child link="middle_left_wheel_link"/>
    <origin rpy="0 0 0" xyz="0 0.2542 -0.255"/>
    <!-- Adjusted Z origin -->
    <axis xyz="0 1 0"/>
    <!-- Axis of rotation for driving -->
  </joint>
  <!-- Middle Right Wheel -->
  <link name="middle_right_wheel_link">
    <visual>
      <origin rpy="1.5707846 0 0" xyz="0 0 0"/>
      <geometry>
        <cylinder length="0.1016" radius="0.0909"/>
      </geometry>
      <material name="black"/>
    </visual>
    <!-- Added Collision -->
    <collision>
      <origin rpy="1.5707846 0 0" xyz="0 0 0"/>
      <geometry>
        <cylinder length="0.1016" radius="0.0909"/>
      </geometry>
    </collision>
    <!-- Added Inertial (PLACEHOLDER VALUES - UPDATE FOR ACCURACY) -->
    <inertial>
      <mass value="0.5"/>
      <!-- Estimated wheel mass in kg -->
      <origin rpy="1.5707846 0 0" xyz="0 0 0"/>
      <inertia ixx="0.001" ixy="0.0" ixz="0.0" iyy="0.0005" iyz="0.0" izz="0.0005"/>
      <!-- Placeholder inertia tensor -->
    </inertial>
  </link>
  <joint name="middle_right_wheel_joint" type="continuous">
    <parent link="base_link"/>
    <child link="middle_right_wheel_link"/>
    <origin rpy="0 0 0" xyz="0 -0.2542 -0.255"/>
    <!-- Adjusted Z origin -->
    <axis xyz="0 1 0"/>
    <!-- Axis of rotation for driving -->
  </joint>
  <!-- Sensors -->
  <link name="gnss_link">
    <visual>
      <origin rpy="0.0 0.0 0.0" xyz="0.0 0.0 0.0"/>
      <geometry>
        <cylinder length="0.02" radius="0.03"/>
      </geometry>
      <material name="sensor_material">
        <!-- Optional: Define sensor material -->
        <color rgba="0.1 0.8 0.1 1.0"/>
      </material>
    </visual>
    <!-- Added Collision -->
    <collision>
      <origin rpy="0.0 0.0 0.0" xyz="0.0 0.0 0.0"/>
      <geometry>
        <cylinder length="0.02" radius="0.03"/>
      </geometry>
    </collision>
    <!-- Added Inertial (PLACEHOLDER VALUES - UPDATE FOR ACCURACY) -->
    <inertial>
      <mass value="0.05"/>
      <!-- Estimated sensor mass -->
      <origin rpy="0.0 0.0 0.0" xyz="0.0 0.0 0.0"/>
      <inertia ixx="1e-6" ixy="0.0" ixz="0.0" iyy="1e-6" iyz="0.0" izz="1e-6"/>
      <!-- Very small inertia -->
    </inertial>
  </link>
  <joint name="gnss_joint" type="fixed">
    <parent link="base_link"/>
    <child link="gnss_link"/>
    <origin rpy="0 0 0" xyz="-0.21 0.07 0.2541"/>
  </joint>
  <link name="imu_link">
    <visual>
      <origin rpy="0.0 0.0 0.0" xyz="0.0 0.0 0.0"/>
      <!-- Simpler rpy for IMU box usually -->
      <geometry>
        <!-- Maybe use a small box for IMU visual/collision -->
        <box size="0.03 0.03 0.01"/>
        <!-- <cylinder radius="${imu_radius}" length="${imu_width}"/> -->
      </geometry>
      <material name="sensor_material"/>
    </visual>
    <!-- Added Collision -->
    <collision>
      <origin rpy="0.0 0.0 0.0" xyz="0.0 0.0 0.0"/>
      <geometry>
        <box size="0.03 0.03 0.01"/>
      </geometry>
    </collision>
    <!-- Added Inertial (PLACEHOLDER VALUES - UPDATE FOR ACCURACY) -->
    <inertial>
      <mass value="0.02"/>
      <!-- Estimated sensor mass -->
      <origin rpy="0.0 0.0 0.0" xyz="0.0 0.0 0.0"/>
      <inertia ixx="1e-7" ixy="0.0" ixz="0.0" iyy="1e-7" iyz="0.0" izz="1e-7"/>
      <!-- Very small inertia -->
    </inertial>
  </link>
  <joint name="imu_joint" type="fixed">
    <parent link="base_link"/>
    <child link="imu_link"/>
    <origin rpy="0 0 0" xyz="-0.21 0.07 0.2541"/>
  </joint>
  <!-- Define materials if not already defined -->
  <material name="black">
    <color rgba="0.0 0.0 0.0 1.0"/>
  </material>
  <material name="Gray">
    <color rgba="0.5 0.5 0.5 1.0"/>
  </material>
  <material name="rover_material">
    <color rgba="0.5 0.5 0.5 1.0"/>
  </material>
  <material name="sensor_material">
    <color rgba="0.1 0.8 0.1 1.0"/>
  </material>
</robot>
